Function call to `process_data` started.
...
Traceback (most recent call last):
  File "main.py", line 50, in <module>
    process_data(data)
  File "main.py", line 32, in process_data
    result = data['key']
KeyError: 'key'
